Workbook

Sheet Capacity
C1: Capacity Dashboard | L1: 190 | M1: 190 | N1: 70 | O1: 70 | Y1: 17 | Z1: 23 | AA1: 29
E2: Areas | L2: Units Capacity by Shitf | P2: Yearly | S2: Daily | V2: Shift | Y2: Monthly
C4: Fiscal Year | D4: Value Strem | E4: Coils | F4: Ecxiters | G4: RF | H4: WC | I4: FA | J4: Total capacity / Shift | K4: Operational Shift Plan | L4: Capacity in 1st | M4: Capacity in 2nd | N4: Capacity in 3rd | O4: Capacity in 4th | P4: Yearly Demand | Q4: Yearly Capacity | R4: Diff | S4: Daily Demand | T4: Daily Capacity | U4: Diff | V4: Shift Demand | W4: Shift Capacity | X4: Diff | Y4: Monthly Demand | Z4: Monthly Capacity | AA4: Diff | AB4: Notes
C5: FY26 | D5: 42 - 44 | F5: 4.5 | G5: 4 | H5: 4 | I5: 4 | J5: =MIN(G5:I5) -> 4 | K5: 1 | L5: =IF($K5=1,$J5*L$1,"") -> 760 | M5: =IF($K5=2,$J5*(M$1+L$1),"") | N5: =IF($K5=3,$J5*(L$1+M$1+N$1),"") | O5: =IF($K5=4,$J5*(L$1+M$1+N$1+O$1),"") | P5: 800 | Q5: =SUM(L5:O5) -> 760 | R5: =Q5-P5 -> -40 | S5: =IFERROR(($P5/(IF($K5=1,$L$1,(IF($K5=2,($M$1),(IF($K5=3,($L$1+($N$1/2)),(IF($K5=4,($L$1+$N$1)))))))))),"") -> 4.2105263 | T5: =J5*K5 -> 4 | U5: =IFERROR((T5-S5),"") -> -0.21052632 | V5: =IFERROR(($P5/(IF($K5=1,$L$1,(IF($K5=2,($L$1+$M$1),(IF($K5=3,($L$1+$M$1+$N$1),(IF($K5=4,($L$1+$M$1+$N$1+$O$1)))))))))),"") -> 4.2105263 | W5: =J5 -> 4 | X5: =IFERROR((W5-V5),"") -> -0.21052632 | Y5: =P5/11.75 -> 68.085106 | Z5: =Q5/11.75 -> 64.680851 | AA5: =Z5-Y5 -> -3.4042553
C6: FY27 | D6: 42 - 44 | J6: =MIN(G6:I6) -> 0 | K6: 0 | L6: =IF($K6=1,$J6*L$1,"") | M6: =IF($K6=2,$J6*(M$1+L$1),"") | N6: =IF($K6=3,$J6*(L$1+M$1+N$1),"") | O6: =IF($K6=4,$J6*(L$1+M$1+N$1+O$1),"") | Q6: =SUM(L6:O6) -> 0 | R6: =Q6-P6 -> 0 | S6: =IFERROR(($P6/(IF($K6=1,$L$1,(IF($K6=2,($M$1),(IF($K6=3,($L$1+($N$1/2)),(IF($K6=4,($L$1+$N$1)))))))))),"") | T6: =J6*2 -> 0 | U6: =IFERROR((T6-S6),"") | V6: =IFERROR((P6/(IF($K6=1,L$1,(IF($K6=2,(L$1+M$1),(IF($K6=3,(L$1+M$1+N$1),(IF($K6=4,(L$1+M$1+N$1+O$1)))))))))),"") | W6: =J6 -> 0 | X6: =IFERROR((W6-V6),"") | Y6: =P6/11.75 -> 0 | Z6: =Q6/11.75 -> 0 | AA6: =Z6-Y6 -> 0
C7: FY28 | D7: 42 - 44 | J7: =MIN(G7:I7) -> 0 | K7: 0 | L7: =IF($K7=1,$J7*L$1,"") | M7: =IF($K7=2,$J7*(M$1+L$1),"") | N7: =IF($K7=3,$J7*(L$1+M$1+N$1),"") | O7: =IF($K7=4,$J7*(L$1+M$1+N$1+O$1),"") | Q7: =SUM(L7:O7) -> 0 | R7: =Q7-P7 -> 0 | S7: =IFERROR(($P7/(IF($K7=1,$L$1,(IF($K7=2,($M$1),(IF($K7=3,($L$1+($N$1/2)),(IF($K7=4,($L$1+$N$1)))))))))),"") | T7: =J7*2 -> 0 | U7: =IFERROR((T7-S7),"") | V7: =IFERROR((P7/(IF($K7=1,L$1,(IF($K7=2,(L$1+M$1),(IF($K7=3,(L$1+M$1+N$1),(IF($K7=4,(L$1+M$1+N$1+O$1)))))))))),"") | W7: =J7 -> 0 | X7: =IFERROR((W7-V7),"") | Y7: =P7/11.75 -> 0 | Z7: =Q7/11.75 -> 0 | AA7: =Z7-Y7 -> 0
C8: FY29 | D8: 42 - 44 | J8: =MIN(G8:I8) -> 0 | K8: 0 | L8: =IF($K8=1,$J8*L$1,"") | M8: =IF($K8=2,$J8*(M$1+L$1),"") | N8: =IF($K8=3,$J8*(L$1+M$1+N$1),"") | O8: =IF($K8=4,$J8*(L$1+M$1+N$1+O$1),"") | Q8: =SUM(L8:O8) -> 0 | R8: =Q8-P8 -> 0 | S8: =IFERROR(($P8/(IF($K8=1,$L$1,(IF($K8=2,($M$1),(IF($K8=3,($L$1+($N$1/2)),(IF($K8=4,($L$1+$N$1)))))))))),"") | T8: =J8*2 -> 0 | U8: =IFERROR((T8-S8),"") | V8: =IFERROR((P8/(IF($K8=1,L$1,(IF($K8=2,(L$1+M$1),(IF($K8=3,(L$1+M$1+N$1),(IF($K8=4,(L$1+M$1+N$1+O$1)))))))))),"") | W8: =J8 -> 0 | X8: =IFERROR((W8-V8),"") | Y8: =P8/11.75 -> 0 | Z8: =Q8/11.75 -> 0 | AA8: =Z8-Y8 -> 0
C9: FY26 | D9: 46's | F9: 2.5 | G9: 2.5 | H9: 2.5 | I9: 2.5 | J9: =MIN(G9:I9) -> 2.5 | K9: 2 | L9: =IF($K9=1,$J9*L$1,"") | M9: =IF($K9=2,$J9*(M$1+L$1),"") -> 950 | N9: =IF($K9=3,$J9*(L$1+M$1+N$1),"") | O9: =IF($K9=4,$J9*(L$1+M$1+N$1+O$1),"") | P9: 822 | Q9: =SUM(L9:O9) -> 950 | R9: =Q9-P9 -> 128 | S9: =IFERROR(($P9/(IF($K9=1,$L$1,(IF($K9=2,($M$1),(IF($K9=3,($L$1+($N$1/2)),(IF($K9=4,($L$1+$N$1)))))))))),"") -> 4.3263158 | T9: =J9*2 -> 5 | U9: =IFERROR((T9-S9),"") -> 0.67368421 | V9: =IFERROR((P9/(IF($K9=1,L$1,(IF($K9=2,(L$1+M$1),(IF($K9=3,(L$1+M$1+N$1),(IF($K9=4,(L$1+M$1+N$1+O$1)))))))))),"") -> 2.1631579 | W9: =J9 -> 2.5 | X9: =IFERROR((W9-V9),"") -> 0.33684211 | Y9: =P9/11.75 -> 69.957447 | Z9: =Q9/11.75 -> 80.851064 | AA9: =Z9-Y9 -> 10.893617
C10: FY27 | D10: 46's | F10: 2.5 | G10: 2.5 | H10: 2.5 | I10: 2.5 | J10: =MIN(G10:I10) -> 2.5 | K10: 2 | L10: =IF($K10=1,$J10*L$1,"") | M10: =IF($K10=2,$J10*(M$1+L$1),"") -> 950 | N10: =IF($K10=3,$J10*(L$1+M$1+N$1),"") | O10: =IF($K10=4,$J10*(L$1+M$1+N$1+O$1),"") | P10: 822 | Q10: =SUM(L10:O10) -> 950 | R10: =Q10-P10 -> 128 | S10: =IFERROR(($P10/(IF($K10=1,$L$1,(IF($K10=2,($M$1),(IF($K10=3,($L$1+($N$1/2)),(IF($K10=4,($L$1+$N$1)))))))))),"") -> 4.3263158 | T10: =J10*2 -> 5 | U10: =IFERROR((T10-S10),"") -> 0.67368421 | V10: =IFERROR((P10/(IF($K10=1,L$1,(IF($K10=2,(L$1+M$1),(IF($K10=3,(L$1+M$1+N$1),(IF($K10=4,(L$1+M$1+N$1+O$1)))))))))),"") -> 2.1631579 | W10: =J10 -> 2.5 | X10: =IFERROR((W10-V10),"") -> 0.33684211 | Y10: =P10/11.75 -> 69.957447 | Z10: =Q10/11.75 -> 80.851064 | AA10: =Z10-Y10 -> 10.893617
C11: FY28 | D11: 46's | J11: =MIN(G11:I11) -> 0 | L11: =IF($K11=1,$J11*L$1,"") | M11: =IF($K11=2,$J11*(M$1+L$1),"") | N11: =IF($K11=3,$J11*(L$1+M$1+N$1),"") | O11: =IF($K11=4,$J11*(L$1+M$1+N$1+O$1),"") | Q11: =SUM(L11:O11) -> 0 | R11: =Q11-P11 -> 0 | S11: =IFERROR(($P11/(IF($K11=1,$L$1,(IF($K11=2,($M$1),(IF($K11=3,($L$1+($N$1/2)),(IF($K11=4,($L$1+$N$1)))))))))),"") | T11: =J11*2 -> 0 | U11: =IFERROR((T11-S11),"") | V11: =IFERROR((P11/(IF($K11=1,L$1,(IF($K11=2,(L$1+M$1),(IF($K11=3,(L$1+M$1+N$1),(IF($K11=4,(L$1+M$1+N$1+O$1)))))))))),"") | W11: =J11 -> 0 | X11: =IFERROR((W11-V11),"") | Y11: =P11/11.75 -> 0 | Z11: =Q11/11.75 -> 0 | AA11: =Z11-Y11 -> 0
C12: FY29 | D12: 46's | J12: =MIN(G12:I12) -> 0 | L12: =IF($K12=1,$J12*L$1,"") | M12: =IF($K12=2,$J12*(M$1+L$1),"") | N12: =IF($K12=3,$J12*(L$1+M$1+N$1),"") | O12: =IF($K12=4,$J12*(L$1+M$1+N$1+O$1),"") | Q12: =SUM(L12:O12) -> 0 | R12: =Q12-P12 -> 0 | S12: =IFERROR(($P12/(IF($K12=1,$L$1,(IF($K12=2,($M$1),(IF($K12=3,($L$1+($N$1/2)),(IF($K12=4,($L$1+$N$1)))))))))),"") | T12: =J12*2 -> 0 | U12: =IFERROR((T12-S12),"") | V12: =IFERROR((P12/(IF($K12=1,L$1,(IF($K12=2,(L$1+M$1),(IF($K12=3,(L$1+M$1+N$1),(IF($K12=4,(L$1+M$1+N$1+O$1)))))))))),"") | W12: =J12 -> 0 | X12: =IFERROR((W12-V12),"") | Y12: =P12/11.75 -> 0 | Z12: =Q12/11.75 -> 0 | AA12: =Z12-Y12 -> 0
C13: FY26 | D13: 47's | F13: 5 | G13: 5 | H13: 5 | I13: 5 | J13: =MIN(G13:I13) -> 5 | K13: 2 | L13: =IF($K13=1,$J13*L$1,"") | M13: =IF($K13=2,$J13*(M$1+L$1),"") -> 1900 | N13: =IF($K13=3,$J13*(L$1+M$1+N$1),"") | O13: =IF($K13=4,$J13*(L$1+M$1+N$1+O$1),"") | P13: 1800 | Q13: =SUM(L13:O13) -> 1900 | R13: =Q13-P13 -> 100 | S13: =IFERROR(($P13/(IF($K13=1,$L$1,(IF($K13=2,($M$1),(IF($K13=3,($L$1+($N$1/2)),(IF($K13=4,($L$1+$N$1)))))))))),"") -> 9.4736842 | T13: =J13*2 -> 10 | U13: =IFERROR((T13-S13),"") -> 0.52631579 | V13: =IFERROR((P13/(IF($K13=1,L$1,(IF($K13=2,(L$1+M$1),(IF($K13=3,(L$1+M$1+N$1),(IF($K13=4,(L$1+M$1+N$1+O$1)))))))))),"") -> 4.7368421 | W13: =J13 -> 5 | X13: =IFERROR((W13-V13),"") -> 0.26315789 | Y13: =P13/11.75 -> 153.19149 | Z13: =Q13/11.75 -> 161.70213 | AA13: =Z13-Y13 -> 8.5106383
C14: FY27 | D14: 47's | F14: 5 | G14: 5 | H14: 5 | I14: 5 | J14: =MIN(G14:I14) -> 5 | K14: 2 | L14: =IF($K14=1,$J14*L$1,"") | M14: =IF($K14=2,$J14*(M$1+L$1),"") -> 1900 | N14: =IF($K14=3,$J14*(L$1+M$1+N$1),"") | O14: =IF($K14=4,$J14*(L$1+M$1+N$1+O$1),"") | P14: 1800 | Q14: =SUM(L14:O14) -> 1900 | R14: =Q14-P14 -> 100 | S14: =IFERROR(($P14/(IF($K14=1,$L$1,(IF($K14=2,($M$1),(IF($K14=3,($L$1+($N$1/2)),(IF($K14=4,($L$1+$N$1)))))))))),"") -> 9.4736842 | T14: =J14*2 -> 10 | U14: =IFERROR((T14-S14),"") -> 0.52631579 | V14: =IFERROR((P14/(IF($K14=1,L$1,(IF($K14=2,(L$1+M$1),(IF($K14=3,(L$1+M$1+N$1),(IF($K14=4,(L$1+M$1+N$1+O$1)))))))))),"") -> 4.7368421 | W14: =J14 -> 5 | X14: =IFERROR((W14-V14),"") -> 0.26315789 | Y14: =P14/11.75 -> 153.19149 | Z14: =Q14/11.75 -> 161.70213 | AA14: =Z14-Y14 -> 8.5106383
C15: FY28 | D15: 47's | J15: =MIN(G15:I15) -> 0 | L15: =IF($K15=1,$J15*L$1,"") | M15: =IF($K15=2,$J15*(M$1+L$1),"") | N15: =IF($K15=3,$J15*(L$1+M$1+N$1),"") | O15: =IF($K15=4,$J15*(L$1+M$1+N$1+O$1),"") | Q15: =SUM(L15:O15) -> 0 | R15: =Q15-P15 -> 0 | S15: =IFERROR(($P15/(IF($K15=1,$L$1,(IF($K15=2,($M$1),(IF($K15=3,($L$1+($N$1/2)),(IF($K15=4,($L$1+$N$1)))))))))),"") | T15: =J15*2 -> 0 | U15: =IFERROR((T15-S15),"") | V15: =IFERROR((P15/(IF($K15=1,L$1,(IF($K15=2,(L$1+M$1),(IF($K15=3,(L$1+M$1+N$1),(IF($K15=4,(L$1+M$1+N$1+O$1)))))))))),"") | W15: =J15 -> 0 | X15: =IFERROR((W15-V15),"") | Y15: =P15/11.75 -> 0 | Z15: =Q15/11.75 -> 0 | AA15: =Z15-Y15 -> 0
C16: FY29 | D16: 47's | J16: =MIN(G16:I16) -> 0 | L16: =IF($K16=1,$J16*L$1,"") | M16: =IF($K16=2,$J16*(M$1+L$1),"") | N16: =IF($K16=3,$J16*(L$1+M$1+N$1),"") | O16: =IF($K16=4,$J16*(L$1+M$1+N$1+O$1),"") | Q16: =SUM(L16:O16) -> 0 | R16: =Q16-P16 -> 0 | S16: =IFERROR(($P16/(IF($K16=1,$L$1,(IF($K16=2,($M$1),(IF($K16=3,($L$1+($N$1/2)),(IF($K16=4,($L$1+$N$1)))))))))),"") | T16: =J16*2 -> 0 | U16: =IFERROR((T16-S16),"") | V16: =IFERROR((P16/(IF($K16=1,L$1,(IF($K16=2,(L$1+M$1),(IF($K16=3,(L$1+M$1+N$1),(IF($K16=4,(L$1+M$1+N$1+O$1)))))))))),"") | W16: =J16 -> 0 | X16: =IFERROR((W16-V16),"") | Y16: =P16/11.75 -> 0 | Z16: =Q16/11.75 -> 0 | AA16: =Z16-Y16 -> 0
C17: FY26 | D17: 49's | F17: 2.5 | G17: 2.5 | H17: 2.5 | I17: 2.5 | J17: =MIN(G17:I17) -> 2.5 | K17: 2 | L17: =IF($K17=1,$J17*L$1,"") | M17: =IF($K17=2,$J17*(M$1+L$1),"") -> 950 | N17: =IF($K17=3,$J17*(L$1+M$1+N$1),"") | O17: =IF($K17=4,$J17*(L$1+M$1+N$1+O$1),"") | P17: 800 | Q17: =SUM(L17:O17) -> 950 | R17: =Q17-P17 -> 150 | S17: =IFERROR(($P17/(IF($K17=1,$L$1,(IF($K17=2,($M$1),(IF($K17=3,($L$1+($N$1/2)),(IF($K17=4,($L$1+$N$1)))))))))),"") -> 4.2105263 | T17: =J17*2 -> 5 | U17: =IFERROR((T17-S17),"") -> 0.78947368 | V17: =IFERROR((P17/(IF($K17=1,L$1,(IF($K17=2,(L$1+M$1),(IF($K17=3,(L$1+M$1+N$1),(IF($K17=4,(L$1+M$1+N$1+O$1)))))))))),"") -> 2.1052632 | W17: =J17 -> 2.5 | X17: =IFERROR((W17-V17),"") -> 0.39473684 | Y17: =P17/11.75 -> 68.085106 | Z17: =Q17/11.75 -> 80.851064 | AA17: =Z17-Y17 -> 12.765957
C18: FY27 | D18: 49's | F18: 2.5 | G18: 2.5 | H18: 2.5 | I18: 2.5 | J18: =MIN(G18:I18) -> 2.5 | K18: 2 | L18: =IF($K18=1,$J18*L$1,"") | M18: =IF($K18=2,$J18*(M$1+L$1),"") -> 950 | N18: =IF($K18=3,$J18*(L$1+M$1+N$1),"") | O18: =IF($K18=4,$J18*(L$1+M$1+N$1+O$1),"") | P18: 800 | Q18: =SUM(L18:O18) -> 950 | R18: =Q18-P18 -> 150 | S18: =IFERROR(($P18/(IF($K18=1,$L$1,(IF($K18=2,($M$1),(IF($K18=3,($L$1+($N$1/2)),(IF($K18=4,($L$1+$N$1)))))))))),"") -> 4.2105263 | T18: =J18*2 -> 5 | U18: =IFERROR((T18-S18),"") -> 0.78947368 | V18: =IFERROR((P18/(IF($K18=1,L$1,(IF($K18=2,(L$1+M$1),(IF($K18=3,(L$1+M$1+N$1),(IF($K18=4,(L$1+M$1+N$1+O$1)))))))))),"") -> 2.1052632 | W18: =J18 -> 2.5 | X18: =IFERROR((W18-V18),"") -> 0.39473684 | Y18: =P18/11.75 -> 68.085106 | Z18: =Q18/11.75 -> 80.851064 | AA18: =Z18-Y18 -> 12.765957
C19: FY28 | D19: 49's | J19: =MIN(G19:I19) -> 0 | L19: =IF($K19=1,$J19*L$1,"") | M19: =IF($K19=2,$J19*(M$1+L$1),"") | N19: =IF($K19=3,$J19*(L$1+M$1+N$1),"") | O19: =IF($K19=4,$J19*(L$1+M$1+N$1+O$1),"") | Q19: =SUM(L19:O19) -> 0 | R19: =Q19-P19 -> 0 | S19: =IFERROR(($P19/(IF($K19=1,$L$1,(IF($K19=2,($M$1),(IF($K19=3,($L$1+($N$1/2)),(IF($K19=4,($L$1+$N$1)))))))))),"") | T19: =J19*2 -> 0 | U19: =IFERROR((T19-S19),"") | V19: =IFERROR((P19/(IF($K19=1,L$1,(IF($K19=2,(L$1+M$1),(IF($K19=3,(L$1+M$1+N$1),(IF($K19=4,(L$1+M$1+N$1+O$1)))))))))),"") | W19: =J19 -> 0 | X19: =IFERROR((W19-V19),"") | Y19: =P19/11.75 -> 0 | Z19: =Q19/11.75 -> 0 | AA19: =Z19-Y19 -> 0
C20: FY29 | D20: 49's | J20: =MIN(G20:I20) -> 0 | L20: =IF($K20=1,$J20*L$1,"") | M20: =IF($K20=2,$J20*(M$1+L$1),"") | N20: =IF($K20=3,$J20*(L$1+M$1+N$1),"") | O20: =IF($K20=4,$J20*(L$1+M$1+N$1+O$1),"") | Q20: =SUM(L20:O20) -> 0 | R20: =Q20-P20 -> 0 | S20: =IFERROR(($P20/(IF($K20=1,$L$1,(IF($K20=2,($M$1),(IF($K20=3,($L$1+($N$1/2)),(IF($K20=4,($L$1+$N$1)))))))))),"") | T20: =J20*2 -> 0 | U20: =IFERROR((T20-S20),"") | V20: =IFERROR((P20/(IF($K20=1,L$1,(IF($K20=2,(L$1+M$1),(IF($K20=3,(L$1+M$1+N$1),(IF($K20=4,(L$1+M$1+N$1+O$1)))))))))),"") | W20: =J20 -> 0 | X20: =IFERROR((W20-V20),"") | Y20: =P20/11.75 -> 0 | Z20: =Q20/11.75 -> 0 | AA20: =Z20-Y20 -> 0
C21: FY26 | D21: 450's | F21: 1 | G21: 1 | H21: 1 | I21: 1 | J21: =MIN(G21:I21) -> 1 | K21: 1 | L21: =IF($K21=1,$J21*L$1,"") -> 190 | M21: =IF($K21=2,$J21*(M$1+L$1),"") | N21: =IF($K21=3,$J21*(L$1+M$1+N$1),"") | O21: =IF($K21=4,$J21*(L$1+M$1+N$1+O$1),"") | P21: 162 | Q21: =SUM(L21:O21) -> 190 | R21: =Q21-P21 -> 28 | S21: =IFERROR(($P21/(IF($K21=1,$L$1,(IF($K21=2,($M$1),(IF($K21=3,($L$1+($N$1/2)),(IF($K21=4,($L$1+$N$1)))))))))),"") -> 0.85263158 | T21: =J21*2 -> 2 | U21: =IFERROR((T21-S21),"") -> 1.1473684 | V21: =IFERROR((P21/(IF($K21=1,L$1,(IF($K21=2,(L$1+M$1),(IF($K21=3,(L$1+M$1+N$1),(IF($K21=4,(L$1+M$1+N$1+O$1)))))))))),"") -> 0.85263158 | W21: =J21 -> 1 | X21: =IFERROR((W21-V21),"") -> 0.14736842 | Y21: =P21/11.75 -> 13.787234 | Z21: =Q21/11.75 -> 16.170213 | AA21: =Z21-Y21 -> 2.3829787
C22: FY27 | D22: 450's | F22: 1 | G22: 1 | H22: 1 | I22: 1 | J22: =MIN(G22:I22) -> 1 | K22: 1 | L22: =IF($K22=1,$J22*L$1,"") -> 190 | M22: =IF($K22=2,$J22*(M$1+L$1),"") | N22: =IF($K22=3,$J22*(L$1+M$1+N$1),"") | O22: =IF($K22=4,$J22*(L$1+M$1+N$1+O$1),"") | P22: 162 | Q22: =SUM(L22:O22) -> 190 | R22: =Q22-P22 -> 28 | S22: =IFERROR(($P22/(IF($K22=1,$L$1,(IF($K22=2,($M$1),(IF($K22=3,($L$1+($N$1/2)),(IF($K22=4,($L$1+$N$1)))))))))),"") -> 0.85263158 | T22: =J22*2 -> 2 | U22: =IFERROR((T22-S22),"") -> 1.1473684 | V22: =IFERROR((P22/(IF($K22=1,L$1,(IF($K22=2,(L$1+M$1),(IF($K22=3,(L$1+M$1+N$1),(IF($K22=4,(L$1+M$1+N$1+O$1)))))))))),"") -> 0.85263158 | W22: =J22 -> 1 | X22: =IFERROR((W22-V22),"") -> 0.14736842 | Y22: =P22/11.75 -> 13.787234 | Z22: =Q22/11.75 -> 16.170213 | AA22: =Z22-Y22 -> 2.3829787
C23: FY28 | D23: 450's | F23: 1 | G23: 1 | H23: 1 | I23: 1 | J23: =MIN(G23:I23) -> 1 | K23: 1 | L23: =IF($K23=1,$J23*L$1,"") -> 190 | M23: =IF($K23=2,$J23*(M$1+L$1),"") | N23: =IF($K23=3,$J23*(L$1+M$1+N$1),"") | O23: =IF($K23=4,$J23*(L$1+M$1+N$1+O$1),"") | P23: 162 | Q23: =SUM(L23:O23) -> 190 | R23: =Q23-P23 -> 28 | S23: =IFERROR(($P23/(IF($K23=1,$L$1,(IF($K23=2,($M$1),(IF($K23=3,($L$1+($N$1/2)),(IF($K23=4,($L$1+$N$1)))))))))),"") -> 0.85263158 | T23: =J23*2 -> 2 | U23: =IFERROR((T23-S23),"") -> 1.1473684 | V23: =IFERROR((P23/(IF($K23=1,L$1,(IF($K23=2,(L$1+M$1),(IF($K23=3,(L$1+M$1+N$1),(IF($K23=4,(L$1+M$1+N$1+O$1)))))))))),"") -> 0.85263158 | W23: =J23 -> 1 | X23: =IFERROR((W23-V23),"") -> 0.14736842 | Y23: =P23/11.75 -> 13.787234 | Z23: =Q23/11.75 -> 16.170213 | AA23: =Z23-Y23 -> 2.3829787
C24: FY29 | D24: 450's | F24: 1 | G24: 1 | H24: 1 | I24: 1 | J24: =MIN(G24:I24) -> 1 | K24: 1 | L24: =IF($K24=1,$J24*L$1,"") -> 190 | M24: =IF($K24=2,$J24*(M$1+L$1),"") | N24: =IF($K24=3,$J24*(L$1+M$1+N$1),"") | O24: =IF($K24=4,$J24*(L$1+M$1+N$1+O$1),"") | P24: 162 | Q24: =SUM(L24:O24) -> 190 | R24: =Q24-P24 -> 28 | S24: =IFERROR(($P24/(IF($K24=1,$L$1,(IF($K24=2,($M$1),(IF($K24=3,($L$1+($N$1/2)),(IF($K24=4,($L$1+$N$1)))))))))),"") -> 0.85263158 | T24: =J24*2 -> 2 | U24: =IFERROR((T24-S24),"") -> 1.1473684 | V24: =IFERROR((P24/(IF($K24=1,L$1,(IF($K24=2,(L$1+M$1),(IF($K24=3,(L$1+M$1+N$1),(IF($K24=4,(L$1+M$1+N$1+O$1)))))))))),"") -> 0.85263158 | W24: =J24 -> 1 | X24: =IFERROR((W24-V24),"") -> 0.14736842 | Y24: =P24/11.75 -> 13.787234 | Z24: =Q24/11.75 -> 16.170213 | AA24: =Z24-Y24 -> 2.3829787
C25: FY26 | D25: 500's | F25: 1 | G25: 1 | H25: 1 | I25: 1 | J25: =MIN(G25:I25) -> 1 | K25: 1 | L25: =IF($K25=1,$J25*L$1,"") -> 190 | M25: =IF($K25=2,$J25*(M$1+L$1),"") | N25: =IF($K25=3,$J25*(L$1+M$1+N$1),"") | O25: =IF($K25=4,$J25*(L$1+M$1+N$1+O$1),"") | P25: 162 | Q25: =SUM(L25:O25) -> 190 | R25: =Q25-P25 -> 28 | S25: =IFERROR(($P25/(IF($K25=1,$L$1,(IF($K25=2,($M$1),(IF($K25=3,($L$1+($N$1/2)),(IF($K25=4,($L$1+$N$1)))))))))),"") -> 0.85263158 | T25: =J25*2 -> 2 | U25: =IFERROR((T25-S25),"") -> 1.1473684 | V25: =IFERROR((P25/(IF($K25=1,L$1,(IF($K25=2,(L$1+M$1),(IF($K25=3,(L$1+M$1+N$1),(IF($K25=4,(L$1+M$1+N$1+O$1)))))))))),"") -> 0.85263158 | W25: =J25 -> 1 | X25: =IFERROR((W25-V25),"") -> 0.14736842 | Y25: =P25/11.75 -> 13.787234 | Z25: =Q25/11.75 -> 16.170213 | AA25: =Z25-Y25 -> 2.3829787
C26: FY27 | D26: 500's | F26: 1 | G26: 1 | H26: 1 | I26: 1 | J26: =MIN(G26:I26) -> 1 | K26: 1 | L26: =IF($K26=1,$J26*L$1,"") -> 190 | M26: =IF($K26=2,$J26*(M$1+L$1),"") | N26: =IF($K26=3,$J26*(L$1+M$1+N$1),"") | O26: =IF($K26=4,$J26*(L$1+M$1+N$1+O$1),"") | P26: 162 | Q26: =SUM(L26:O26) -> 190 | R26: =Q26-P26 -> 28 | S26: =IFERROR(($P26/(IF($K26=1,$L$1,(IF($K26=2,($M$1),(IF($K26=3,($L$1+($N$1/2)),(IF($K26=4,($L$1+$N$1)))))))))),"") -> 0.85263158 | T26: =J26*2 -> 2 | U26: =IFERROR((T26-S26),"") -> 1.1473684 | V26: =IFERROR((P26/(IF($K26=1,L$1,(IF($K26=2,(L$1+M$1),(IF($K26=3,(L$1+M$1+N$1),(IF($K26=4,(L$1+M$1+N$1+O$1)))))))))),"") -> 0.85263158 | W26: =J26 -> 1 | X26: =IFERROR((W26-V26),"") -> 0.14736842 | Y26: =P26/11.75 -> 13.787234 | Z26: =Q26/11.75 -> 16.170213 | AA26: =Z26-Y26 -> 2.3829787
C27: FY28 | D27: 500's | F27: 1 | G27: 1 | H27: 1 | I27: 1 | J27: =MIN(G27:I27) -> 1 | K27: 1 | L27: =IF($K27=1,$J27*L$1,"") -> 190 | M27: =IF($K27=2,$J27*(M$1+L$1),"") | N27: =IF($K27=3,$J27*(L$1+M$1+N$1),"") | O27: =IF($K27=4,$J27*(L$1+M$1+N$1+O$1),"") | P27: 162 | Q27: =SUM(L27:O27) -> 190 | R27: =Q27-P27 -> 28 | S27: =IFERROR(($P27/(IF($K27=1,$L$1,(IF($K27=2,($M$1),(IF($K27=3,($L$1+($N$1/2)),(IF($K27=4,($L$1+$N$1)))))))))),"") -> 0.85263158 | T27: =J27*2 -> 2 | U27: =IFERROR((T27-S27),"") -> 1.1473684 | V27: =IFERROR((P27/(IF($K27=1,L$1,(IF($K27=2,(L$1+M$1),(IF($K27=3,(L$1+M$1+N$1),(IF($K27=4,(L$1+M$1+N$1+O$1)))))))))),"") -> 0.85263158 | W27: =J27 -> 1 | X27: =IFERROR((W27-V27),"") -> 0.14736842 | Y27: =P27/11.75 -> 13.787234 | Z27: =Q27/11.75 -> 16.170213 | AA27: =Z27-Y27 -> 2.3829787
C28: FY29 | D28: 500's | F28: 1 | G28: 1 | H28: 1 | I28: 1 | J28: =MIN(G28:I28) -> 1 | K28: 1 | L28: =IF($K28=1,$J28*L$1,"") -> 190 | M28: =IF($K28=2,$J28*(M$1+L$1),"") | N28: =IF($K28=3,$J28*(L$1+M$1+N$1),"") | O28: =IF($K28=4,$J28*(L$1+M$1+N$1+O$1),"") | P28: 162 | Q28: =SUM(L28:O28) -> 190 | R28: =Q28-P28 -> 28 | S28: =IFERROR(($P28/(IF($K28=1,$L$1,(IF($K28=2,($M$1),(IF($K28=3,($L$1+($N$1/2)),(IF($K28=4,($L$1+$N$1)))))))))),"") -> 0.85263158 | T28: =J28*2 -> 2 | U28: =IFERROR((T28-S28),"") -> 1.1473684 | V28: =IFERROR((P28/(IF($K28=1,L$1,(IF($K28=2,(L$1+M$1),(IF($K28=3,(L$1+M$1+N$1),(IF($K28=4,(L$1+M$1+N$1+O$1)))))))))),"") -> 0.85263158 | W28: =J28 -> 1 | X28: =IFERROR((W28-V28),"") -> 0.14736842 | Y28: =P28/11.75 -> 13.787234 | Z28: =Q28/11.75 -> 16.170213 | AA28: =Z28-Y28 -> 2.3829787
C29: FY26 | D29: 1200 / 930 | F29: 1.5 | G29: 1.5 | H29: 1.5 | I29: 1.5 | J29: =MIN(G29:I29) -> 1.5 | K29: 1 | L29: =IF($K29=1,$J29*L$1,"") -> 285 | M29: =IF($K29=2,$J29*(M$1+L$1),"") | N29: =IF($K29=3,$J29*(L$1+M$1+N$1),"") | O29: =IF($K29=4,$J29*(L$1+M$1+N$1+O$1),"") | P29: 240 | Q29: =SUM(L29:O29) -> 285 | R29: =Q29-P29 -> 45 | S29: =IFERROR(($P29/(IF($K29=1,$L$1,(IF($K29=2,($M$1),(IF($K29=3,($L$1+($N$1/2)),(IF($K29=4,($L$1+$N$1)))))))))),"") -> 1.2631579 | T29: =J29*2 -> 3 | U29: =IFERROR((T29-S29),"") -> 1.7368421 | V29: =IFERROR((P29/(IF($K29=1,L$1,(IF($K29=2,(L$1+M$1),(IF($K29=3,(L$1+M$1+N$1),(IF($K29=4,(L$1+M$1+N$1+O$1)))))))))),"") -> 1.2631579 | W29: =J29 -> 1.5 | X29: =IFERROR((W29-V29),"") -> 0.23684211 | Y29: =P29/11.75 -> 20.425532 | Z29: =Q29/11.75 -> 24.255319 | AA29: =Z29-Y29 -> 3.8297872
C30: FY27 | D30: 1200 / 930 | F30: 1.5 | G30: 1.5 | H30: 1.5 | I30: 1.5 | J30: =MIN(G30:I30) -> 1.5 | K30: 1 | L30: =IF($K30=1,$J30*L$1,"") -> 285 | M30: =IF($K30=2,$J30*(M$1+L$1),"") | N30: =IF($K30=3,$J30*(L$1+M$1+N$1),"") | O30: =IF($K30=4,$J30*(L$1+M$1+N$1+O$1),"") | P30: 240 | Q30: =SUM(L30:O30) -> 285 | R30: =Q30-P30 -> 45 | S30: =IFERROR(($P30/(IF($K30=1,$L$1,(IF($K30=2,($M$1),(IF($K30=3,($L$1+($N$1/2)),(IF($K30=4,($L$1+$N$1)))))))))),"") -> 1.2631579 | T30: =J30*2 -> 3 | U30: =IFERROR((T30-S30),"") -> 1.7368421 | V30: =IFERROR((P30/(IF($K30=1,L$1,(IF($K30=2,(L$1+M$1),(IF($K30=3,(L$1+M$1+N$1),(IF($K30=4,(L$1+M$1+N$1+O$1)))))))))),"") -> 1.2631579 | W30: =J30 -> 1.5 | X30: =IFERROR((W30-V30),"") -> 0.23684211 | Y30: =P30/11.75 -> 20.425532 | Z30: =Q30/11.75 -> 24.255319 | AA30: =Z30-Y30 -> 3.8297872
C31: FY28 | D31: 1200 / 930 | F31: 1.5 | G31: 1.5 | H31: 1.5 | I31: 1.5 | J31: =MIN(G31:I31) -> 1.5 | K31: 1 | L31: =IF($K31=1,$J31*L$1,"") -> 285 | M31: =IF($K31=2,$J31*(M$1+L$1),"") | N31: =IF($K31=3,$J31*(L$1+M$1+N$1),"") | O31: =IF($K31=4,$J31*(L$1+M$1+N$1+O$1),"") | P31: 240 | Q31: =SUM(L31:O31) -> 285 | R31: =Q31-P31 -> 45 | S31: =IFERROR(($P31/(IF($K31=1,$L$1,(IF($K31=2,($M$1),(IF($K31=3,($L$1+($N$1/2)),(IF($K31=4,($L$1+$N$1)))))))))),"") -> 1.2631579 | T31: =J31*2 -> 3 | U31: =IFERROR((T31-S31),"") -> 1.7368421 | V31: =IFERROR((P31/(IF($K31=1,L$1,(IF($K31=2,(L$1+M$1),(IF($K31=3,(L$1+M$1+N$1),(IF($K31=4,(L$1+M$1+N$1+O$1)))))))))),"") -> 1.2631579 | W31: =J31 -> 1.5 | X31: =IFERROR((W31-V31),"") -> 0.23684211 | Y31: =P31/11.75 -> 20.425532 | Z31: =Q31/11.75 -> 24.255319 | AA31: =Z31-Y31 -> 3.8297872
C32: FY29 | D32: 1200 / 930 | F32: 1.5 | G32: 1.5 | H32: 1.5 | I32: 1.5 | J32: =MIN(G32:I32) -> 1.5 | K32: 1 | L32: =IF($K32=1,$J32*L$1,"") -> 285 | M32: =IF($K32=2,$J32*(M$1+L$1),"") | N32: =IF($K32=3,$J32*(L$1+M$1+N$1),"") | O32: =IF($K32=4,$J32*(L$1+M$1+N$1+O$1),"") | P32: 240 | Q32: =SUM(L32:O32) -> 285 | R32: =Q32-P32 -> 45 | S32: =IFERROR(($P32/(IF($K32=1,$L$1,(IF($K32=2,($M$1),(IF($K32=3,($L$1+($N$1/2)),(IF($K32=4,($L$1+$N$1)))))))))),"") -> 1.2631579 | T32: =J32*2 -> 3 | U32: =IFERROR((T32-S32),"") -> 1.7368421 | V32: =IFERROR((P32/(IF($K32=1,L$1,(IF($K32=2,(L$1+M$1),(IF($K32=3,(L$1+M$1+N$1),(IF($K32=4,(L$1+M$1+N$1+O$1)))))))))),"") -> 1.2631579 | W32: =J32 -> 1.5 | X32: =IFERROR((W32-V32),"") -> 0.23684211 | Y32: =P32/11.75 -> 20.425532 | Z32: =Q32/11.75 -> 24.255319 | AA32: =Z32-Y32 -> 3.8297872
... C37: FY26 | D37: 1600 / 641 | F37: 4 | G37: 4 | H37: 4 | I37: 4 | J37: =MIN(G37:I37) -> 4 | K37: 4 | L37: =IF($K37=1,$J37*L$1,"") | M37: =IF($K37=2,$J37*(M$1+L$1),"") | N37: =IF($K37=3,$J37*(L$1+M$1+N$1),"") | O37: =IF($K37=4,$J37*(L$1+M$1+N$1+O$1),"") -> 2080 | P37: 1872 | Q37: =SUM(L37:O37) -> 2080 | R37: =Q37-P37 -> 208 | S37: =IFERROR(($P37/(IF($K37=1,$L$1,(IF($K37=2,($M$1),(IF($K37=3,($L$1+($N$1/2)),(IF($K37=4,($L$1+$N$1)))))))))),"") -> 7.2 | T37: =J37*2 -> 8 | U37: =IFERROR((T37-S37),"") -> 0.8 | V37: =IFERROR((P37/(IF($K37=1,L$1,(IF($K37=2,(L$1+M$1),(IF($K37=3,(L$1+M$1+N$1),(IF($K37=4,(L$1+M$1+N$1+O$1)))))))))),"") -> 3.6 | W37: =J37 -> 4 | X37: =IFERROR((W37-V37),"") -> 0.4 | Y37: =P37/11.75 -> 159.31915 | Z37: =Q37/11.75 -> 177.02128 | AA37: =Z37-Y37 -> 17.702128
C38: FY27 | D38: 1600 / 641 | G38: 4 | H38: 4 | I38: 4 | J38: =MIN(G38:I38) -> 4 | K38: 2 | L38: =IF($K38=1,$J38*L$1,"") | M38: =IF($K38=2,$J38*(M$1+L$1),"") -> 1520 | N38: =IF($K38=3,$J38*(L$1+M$1+N$1),"") | O38: =IF($K38=4,$J38*(L$1+M$1+N$1+O$1),"") | P38: 1427 | Q38: =SUM(L38:O38) -> 1520 | R38: =Q38-P38 -> 93 | S38: =IFERROR(($P38/(IF($K38=1,$L$1,(IF($K38=2,($M$1),(IF($K38=3,($L$1+($N$1/2)),(IF($K38=4,($L$1+$N$1)))))))))),"") -> 7.5105263 | T38: =J38*2 -> 8 | U38: =IFERROR((T38-S38),"") -> 0.48947368 | V38: =IFERROR((P38/(IF($K38=1,L$1,(IF($K38=2,(L$1+M$1),(IF($K38=3,(L$1+M$1+N$1),(IF($K38=4,(L$1+M$1+N$1+O$1)))))))))),"") -> 3.7552632 | W38: =J38 -> 4 | X38: =IFERROR((W38-V38),"") -> 0.24473684 | Y38: =P38/11.75 -> 121.44681 | Z38: =Q38/11.75 -> 129.3617 | AA38: =Z38-Y38 -> 7.9148936
C39: FY28 | D39: 1600 / 641 | F39: 4.1 | G39: 4.1 | H39: 4.1 | I39: 4.1 | J39: =MIN(G39:I39) -> 4.1 | K39: 2 | L39: =IF($K39=1,$J39*L$1,"") | M39: =IF($K39=2,$J39*(M$1+L$1),"") -> 1558 | N39: =IF($K39=3,$J39*(L$1+M$1+N$1),"") | O39: =IF($K39=4,$J39*(L$1+M$1+N$1+O$1),"") | P39: 1564 | Q39: =SUM(L39:O39) -> 1558 | R39: =Q39-P39 -> -6 | S39: =IFERROR(($P39/(IF($K39=1,$L$1,(IF($K39=2,($M$1),(IF($K39=3,($L$1+($N$1/2)),(IF($K39=4,($L$1+$N$1)))))))))),"") -> 8.2315789 | T39: =J39*2 -> 8.2 | U39: =IFERROR((T39-S39),"") -> -0.031578947 | V39: =IFERROR((P39/(IF($K39=1,L$1,(IF($K39=2,(L$1+M$1),(IF($K39=3,(L$1+M$1+N$1),(IF($K39=4,(L$1+M$1+N$1+O$1)))))))))),"") -> 4.1157895 | W39: =J39 -> 4.1 | X39: =IFERROR((W39-V39),"") -> -0.015789474 | Y39: =P39/11.75 -> 133.10638 | Z39: =Q39/11.75 -> 132.59574 | AA39: =Z39-Y39 -> -0.5106383
C40: FY29 | D40: 1600 / 641 | G40: 4 | H40: 4 | I40: 4 | J40: =MIN(G40:I40) -> 4 | K40: 3 | L40: =IF($K40=1,$J40*L$1,"") | M40: =IF($K40=2,$J40*(M$1+L$1),"") | N40: =IF($K40=3,$J40*(L$1+M$1+N$1),"") -> 1800 | O40: =IF($K40=4,$J40*(L$1+M$1+N$1+O$1),"") | P40: 1663 | Q40: =SUM(L40:O40) -> 1800 | R40: =Q40-P40 -> 137 | S40: =IFERROR(($P40/(IF($K40=1,$L$1,(IF($K40=2,($M$1),(IF($K40=3,($L$1+($N$1/2)),(IF($K40=4,($L$1+$N$1)))))))))),"") -> 7.3911111 | T40: =J40*2 -> 8 | U40: =IFERROR((T40-S40),"") -> 0.60888889 | V40: =IFERROR((P40/(IF($K40=1,L$1,(IF($K40=2,(L$1+M$1),(IF($K40=3,(L$1+M$1+N$1),(IF($K40=4,(L$1+M$1+N$1+O$1)))))))))),"") -> 3.6955556 | W40: =J40 -> 4 | X40: =IFERROR((W40-V40),"") -> 0.30444444 | Y40: =P40/11.75 -> 141.53191 | Z40: =Q40/11.75 -> 153.19149 | AA40: =Z40-Y40 -> 11.659574
C41: FY26 | D41: 1800's | E41: 8 | F41: 8 | G41: 8 | H41: 8 | I41: 8 | J41: =MIN(G41:I41) -> 8 | K41: 4 | L41: =IF($K41=1,$J41*L$1,"") | M41: =IF($K41=2,$J41*(M$1+L$1),"") | N41: =IF($K41=3,$J41*(L$1+M$1+N$1),"") | O41: =IF($K41=4,$J41*(L$1+M$1+N$1+O$1),"") -> 4160 | P41: 5117 | Q41: =SUM(L41:O41) -> 4160 | R41: =Q41-P41 -> -957 | S41: =IFERROR(($P41/(IF($K41=1,$L$1,(IF($K41=2,($M$1),(IF($K41=3,($L$1+($N$1/2)),(IF($K41=4,($L$1+$N$1)))))))))),"") -> 19.680769 | T41: =J41*2 -> 16 | U41: =IFERROR((T41-S41),"") -> -3.6807692 | V41: =IFERROR((P41/(IF($K41=1,L$1,(IF($K41=2,(L$1+M$1),(IF($K41=3,(L$1+M$1+N$1),(IF($K41=4,(L$1+M$1+N$1+O$1)))))))))),"") -> 9.8403846 | W41: =J41 -> 8 | X41: =IFERROR((W41-V41),"") -> -1.8403846 | Y41: =P41/11.75 -> 435.48936 | Z41: =Q41/11.75 -> 354.04255 | AA41: =Z41-Y41 -> -81.446809
C42: FY27 | D42: 1800's | E42: 10 | F42: 10 | G42: 10 | H42: 10.3 | I42: 11 | J42: =MIN(G42:I42) -> 10 | K42: 4 | L42: =IF($K42=1,$J42*L$1,"") | M42: =IF($K42=2,$J42*(M$1+L$1),"") | N42: =IF($K42=3,$J42*(L$1+M$1+N$1),"") | O42: =IF($K42=4,$J42*(L$1+M$1+N$1+O$1),"") -> 5200 | P42: 6916 | Q42: =SUM(L42:O42) -> 5200 | R42: =Q42-P42 -> -1716 | S42: =IFERROR(($P42/(IF($K42=1,$L$1,(IF($K42=2,($M$1),(IF($K42=3,($L$1+($N$1/2)),(IF($K42=4,($L$1+$N$1)))))))))),"") -> 26.6 | T42: =J42*2 -> 20 | U42: =IFERROR((T42-S42),"") -> -6.6 | V42: =IFERROR((P42/(IF($K42=1,L$1,(IF($K42=2,(L$1+M$1),(IF($K42=3,(L$1+M$1+N$1),(IF($K42=4,(L$1+M$1+N$1+O$1)))))))))),"") -> 13.3 | W42: =J42 -> 10 | X42: =IFERROR((W42-V42),"") -> -3.3 | Y42: =P42/11.75 -> 588.59574 | Z42: =Q42/11.75 -> 442.55319 | AA42: =Z42-Y42 -> -146.04255
C43: FY28 | D43: 1800's | E43: 17 | F43: 17 | G43: 17 | H43: 17 | I43: 17 | J43: =MIN(G43:I43) -> 17 | K43: 4 | L43: =IF($K43=1,$J43*L$1,"") | M43: =IF($K43=2,$J43*(M$1+L$1),"") | N43: =IF($K43=3,$J43*(L$1+M$1+N$1),"") | O43: =IF($K43=4,$J43*(L$1+M$1+N$1+O$1),"") -> 8840 | P43: 11604 | Q43: =SUM(L43:O43) -> 8840 | R43: =Q43-P43 -> -2764 | S43: =IFERROR(($P43/(IF($K43=1,$L$1,(IF($K43=2,($M$1),(IF($K43=3,($L$1+($N$1/2)),(IF($K43=4,($L$1+$N$1)))))))))),"") -> 44.630769 | T43: =J43*2 -> 34 | U43: =IFERROR((T43-S43),"") -> -10.630769 | V43: =IFERROR((P43/(IF($K43=1,L$1,(IF($K43=2,(L$1+M$1),(IF($K43=3,(L$1+M$1+N$1),(IF($K43=4,(L$1+M$1+N$1+O$1)))))))))),"") -> 22.315385 | W43: =J43 -> 17 | X43: =IFERROR((W43-V43),"") -> -5.3153846 | Y43: =P43/11.75 -> 987.57447 | Z43: =Q43/11.75 -> 752.34043 | AA43: =Z43-Y43 -> -235.23404
C44: FY29 | D44: 1800's | E44: 16 | F44: 16 | G44: 20 | H44: 20 | I44: 20 | J44: =MIN(G44:I44) -> 20 | K44: 4 | L44: =IF($K44=1,$J44*L$1,"") | M44: =IF($K44=2,$J44*(M$1+L$1),"") | N44: =IF($K44=3,$J44*(L$1+M$1+N$1),"") | O44: =IF($K44=4,$J44*(L$1+M$1+N$1+O$1),"") -> 10400 | P44: 12630 | Q44: =SUM(L44:O44) -> 10400 | R44: =Q44-P44 -> -2230 | S44: =IFERROR(($P44/(IF($K44=1,$L$1,(IF($K44=2,($M$1),(IF($K44=3,($L$1+($N$1/2)),(IF($K44=4,($L$1+$N$1)))))))))),"") -> 48.576923 | T44: =J44*2 -> 40 | U44: =IFERROR((T44-S44),"") -> -8.5769231 | V44: =IFERROR((P44/(IF($K44=1,L$1,(IF($K44=2,(L$1+M$1),(IF($K44=3,(L$1+M$1+N$1),(IF($K44=4,(L$1+M$1+N$1+O$1)))))))))),"") -> 24.288462 | W44: =J44 -> 20 | X44: =IFERROR((W44-V44),"") -> -4.2884615 | Y44: =P44/11.75 -> 1074.8936 | Z44: =Q44/11.75 -> 885.10638 | AA44: =Z44-Y44 -> -189.78723
C45: FY26 | D45: 841's | G45: 0 | H45: 0 | I45: 0 | J45: =MIN(G45:I45) -> 0 | K45: 3 | L45: =IF($K45=1,$J45*L$1,"") | M45: =IF($K45=2,$J45*(M$1+L$1),"") | N45: =IF($K45=3,$J45*(L$1+M$1+N$1),"") -> 0 | O45: =IF($K45=4,$J45*(L$1+M$1+N$1+O$1),"") | Q45: =SUM(L45:O45) -> 0 | R45: =Q45-P45 -> 0 | S45: =IFERROR(($P45/(IF($K45=1,$L$1,(IF($K45=2,($M$1),(IF($K45=3,($L$1+($N$1/2)),(IF($K45=4,($L$1+$N$1)))))))))),"") -> 0 | T45: =J45*2 -> 0 | U45: =IFERROR((T45-S45),"") -> 0 | V45: =IFERROR((P45/(IF($K45=1,L$1,(IF($K45=2,(L$1+M$1),(IF($K45=3,(L$1+M$1+N$1),(IF($K45=4,(L$1+M$1+N$1+O$1)))))))))),"") -> 0 | W45: =J45 -> 0 | X45: =IFERROR((W45-V45),"") -> 0 | Y45: =P45/11.75 -> 0 | Z45: =Q45/11.75 -> 0 | AA45: =Z45-Y45 -> 0
...

Sheet Cap Updt
A1: Fiscal Year | B1: FY Order | C1: Value Stream | D1: Area | E1: Capacity / Area | F1: Total Capacity / Shift | G1: Operational Shift Plan | H1: Capacity in 1st | I1: Capacity in 2nd | J1: Capacity in 3rd | K1: Capacity in 4th | L1: Demand Type | M1: Demand | N1: Capacity | O1: Diff
A2: FY26 | B2: 1 | C2: 42-44 | D2: Coils | E2: =Capacity!E5 -> 0 | F2: =Capacity!$J$5 -> 4 | G2: =Capacity!$K$5 -> 1 | H2: =Capacity!$L$5 -> 760 | I2: =Capacity!$M$5 | J2: =Capacity!$N$5 | K2: =Capacity!$O$5 | L2: Yearly | M2: =Capacity!$P$5 -> 800 | N2: =Capacity!$Q$5 -> 760 | O2: =Capacity!$R$5 -> -40
A3: FY26 | B3: 1 | C3: 42-44 | D3: Exciters | E3: =Capacity!F5 -> 4.5 | F3: =Capacity!$J$5 -> 4 | G3: =Capacity!$K$5 -> 1 | H3: =Capacity!$L$5 -> 760 | I3: =Capacity!$M$5 | J3: =Capacity!$N$5 | K3: =Capacity!$O$5 | L3: Yearly | M3: =Capacity!$P$5 -> 800 | N3: =Capacity!$Q$5 -> 760 | O3: =Capacity!$R$5 -> -40
A4: FY26 | B4: 1 | C4: 42-44 | D4: RF | E4: =Capacity!G5 -> 4 | F4: =Capacity!$J$5 -> 4 | G4: =Capacity!$K$5 -> 1 | H4: =Capacity!$L$5 -> 760 | I4: =Capacity!$M$5 | J4: =Capacity!$N$5 | K4: =Capacity!$O$5 | L4: Yearly | M4: =Capacity!$P$5 -> 800 | N4: =Capacity!$Q$5 -> 760 | O4: =Capacity!$R$5 -> -40
A5: FY26 | B5: 1 | C5: 42-44 | D5: WC | E5: =Capacity!H5 -> 4 | F5: =Capacity!$J$5 -> 4 | G5: =Capacity!$K$5 -> 1 | H5: =Capacity!$L$5 -> 760 | I5: =Capacity!$M$5 | J5: =Capacity!$N$5 | K5: =Capacity!$O$5 | L5: Yearly | M5: =Capacity!$P$5 -> 800 | N5: =Capacity!$Q$5 -> 760 | O5: =Capacity!$R$5 -> -40
A6: FY26 | B6: 1 | C6: 42-44 | D6: FA | E6: =Capacity!I5 -> 4 | F6: =Capacity!$J$5 -> 4 | G6: =Capacity!$K$5 -> 1 | H6: =Capacity!$L$5 -> 760 | I6: =Capacity!$M$5 | J6: =Capacity!$N$5 | K6: =Capacity!$O$5 | L6: Yearly | M6: =Capacity!$P$5 -> 800 | N6: =Capacity!$Q$5 -> 760 | O6: =Capacity!$R$5 -> -40
A7: FY26 | B7: 1 | C7: 42-44 | D7: Coils | E7: =Capacity!E5 -> 0 | F7: =Capacity!$J$5 -> 4 | G7: =Capacity!$K$5 -> 1 | H7: =Capacity!$L$5 -> 760 | I7: =Capacity!$M$5 | J7: =Capacity!$N$5 | K7: =Capacity!$O$5 | L7: Daily | M7: =Capacity!$S$5 -> 4.2105263 | N7: =Capacity!$T$5 -> 4 | O7: =Capacity!$U$5 -> -0.21052632
A8: FY26 | B8: 1 | C8: 42-44 | D8: Exciters | E8: =Capacity!F5 -> 4.5 | F8: =Capacity!$J$5 -> 4 | G8: =Capacity!$K$5 -> 1 | H8: =Capacity!$L$5 -> 760 | I8: =Capacity!$M$5 | J8: =Capacity!$N$5 | K8: =Capacity!$O$5 | L8: Daily | M8: =Capacity!$S$5 -> 4.2105263 | N8: =Capacity!$T$5 -> 4 | O8: =Capacity!$U$5 -> -0.21052632
A9: FY26 | B9: 1 | C9: 42-44 | D9: RF | E9: =Capacity!G5 -> 4 | F9: =Capacity!$J$5 -> 4 | G9: =Capacity!$K$5 -> 1 | H9: =Capacity!$L$5 -> 760 | I9: =Capacity!$M$5 | J9: =Capacity!$N$5 | K9: =Capacity!$O$5 | L9: Daily | M9: =Capacity!$S$5 -> 4.2105263 | N9: =Capacity!$T$5 -> 4 | O9: =Capacity!$U$5 -> -0.21052632
A10: FY26 | B10: 1 | C10: 42-44 | D10: WC | E10: =Capacity!H5 -> 4 | F10: =Capacity!$J$5 -> 4 | G10: =Capacity!$K$5 -> 1 | H10: =Capacity!$L$5 -> 760 | I10: =Capacity!$M$5 | J10: =Capacity!$N$5 | K10: =Capacity!$O$5 | L10: Daily | M10: =Capacity!$S$5 -> 4.2105263 | N10: =Capacity!$T$5 -> 4 | O10: =Capacity!$U$5 -> -0.21052632
A11: FY26 | B11: 1 | C11: 42-44 | D11: FA | E11: =Capacity!I5 -> 4 | F11: =Capacity!$J$5 -> 4 | G11: =Capacity!$K$5 -> 1 | H11: =Capacity!$L$5 -> 760 | I11: =Capacity!$M$5 | J11: =Capacity!$N$5 | K11: =Capacity!$O$5 | L11: Daily | M11: =Capacity!$S$5 -> 4.2105263 | N11: =Capacity!$T$5 -> 4 | O11: =Capacity!$U$5 -> -0.21052632
A12: FY26 | B12: 1 | C12: 42-44 | D12: Coils | E12: =Capacity!E5 -> 0 | F12: =Capacity!$J$5 -> 4 | G12: =Capacity!$K$5 -> 1 | H12: =Capacity!$L$5 -> 760 | I12: =Capacity!$M$5 | J12: =Capacity!$N$5 | K12: =Capacity!$O$5 | L12: Shift | M12: =Capacity!$V$5 -> 4.2105263 | N12: =Capacity!$W$5 -> 4 | O12: =Capacity!$X$5 -> -0.21052632
A13: FY26 | B13: 1 | C13: 42-44 | D13: Exciters | E13: =Capacity!F5 -> 4.5 | F13: =Capacity!$J$5 -> 4 | G13: =Capacity!$K$5 -> 1 | H13: =Capacity!$L$5 -> 760 | I13: =Capacity!$M$5 | J13: =Capacity!$N$5 | K13: =Capacity!$O$5 | L13: Shift | M13: =Capacity!$V$5 -> 4.2105263 | N13: =Capacity!$W$5 -> 4 | O13: =Capacity!$X$5 -> -0.21052632
A14: FY26 | B14: 1 | C14: 42-44 | D14: RF | E14: =Capacity!G5 -> 4 | F14: =Capacity!$J$5 -> 4 | G14: =Capacity!$K$5 -> 1 | H14: =Capacity!$L$5 -> 760 | I14: =Capacity!$M$5 | J14: =Capacity!$N$5 | K14: =Capacity!$O$5 | L14: Shift | M14: =Capacity!$V$5 -> 4.2105263 | N14: =Capacity!$W$5 -> 4 | O14: =Capacity!$X$5 -> -0.21052632
A15: FY26 | B15: 1 | C15: 42-44 | D15: WC | E15: =Capacity!H5 -> 4 | F15: =Capacity!$J$5 -> 4 | G15: =Capacity!$K$5 -> 1 | H15: =Capacity!$L$5 -> 760 | I15: =Capacity!$M$5 | J15: =Capacity!$N$5 | K15: =Capacity!$O$5 | L15: Shift | M15: =Capacity!$V$5 -> 4.2105263 | N15: =Capacity!$W$5 -> 4 | O15: =Capacity!$X$5 -> -0.21052632
A16: FY26 | B16: 1 | C16: 42-44 | D16: FA | E16: =Capacity!I5 -> 4 | F16: =Capacity!$J$5 -> 4 | G16: =Capacity!$K$5 -> 1 | H16: =Capacity!$L$5 -> 760 | I16: =Capacity!$M$5 | J16: =Capacity!$N$5 | K16: =Capacity!$O$5 | L16: Shift | M16: =Capacity!$V$5 -> 4.2105263 | N16: =Capacity!$W$5 -> 4 | O16: =Capacity!$X$5 -> -0.21052632
A17: FY26 | B17: 1 | C17: 42-44 | D17: Coils | E17: =Capacity!E5 -> 0 | F17: =Capacity!$J$5 -> 4 | G17: =Capacity!$K$5 -> 1 | H17: =Capacity!$L$5 -> 760 | I17: =Capacity!$M$5 | J17: =Capacity!$N$5 | K17: =Capacity!$O$5 | L17: Monthly | M17: =Capacity!$Y$5 -> 68.085106 | N17: =Capacity!$Z$5 -> 64.680851 | O17: =Capacity!$AA$5 -> -3.4042553
A18: FY26 | B18: 1 | C18: 42-44 | D18: Exciters | E18: =Capacity!F5 -> 4.5 | F18: =Capacity!$J$5 -> 4 | G18: =Capacity!$K$5 -> 1 | H18: =Capacity!$L$5 -> 760 | I18: =Capacity!$M$5 | J18: =Capacity!$N$5 | K18: =Capacity!$O$5 | L18: Monthly | M18: =Capacity!$Y$5 -> 68.085106 | N18: =Capacity!$Z$5 -> 64.680851 | O18: =Capacity!$AA$5 -> -3.4042553
A19: FY26 | B19: 1 | C19: 42-44 | D19: RF | E19: =Capacity!G5 -> 4 | F19: =Capacity!$J$5 -> 4 | G19: =Capacity!$K$5 -> 1 | H19: =Capacity!$L$5 -> 760 | I19: =Capacity!$M$5 | J19: =Capacity!$N$5 | K19: =Capacity!$O$5 | L19: Monthly | M19: =Capacity!$Y$5 -> 68.085106 | N19: =Capacity!$Z$5 -> 64.680851 | O19: =Capacity!$AA$5 -> -3.4042553
A20: FY26 | B20: 1 | C20: 42-44 | D20: WC | E20: =Capacity!H5 -> 4 | F20: =Capacity!$J$5 -> 4 | G20: =Capacity!$K$5 -> 1 | H20: =Capacity!$L$5 -> 760 | I20: =Capacity!$M$5 | J20: =Capacity!$N$5 | K20: =Capacity!$O$5 | L20: Monthly | M20: =Capacity!$Y$5 -> 68.085106 | N20: =Capacity!$Z$5 -> 64.680851 | O20: =Capacity!$AA$5 -> -3.4042553
A21: FY26 | B21: 1 | C21: 42-44 | D21: FA | E21: =Capacity!I5 -> 4 | F21: =Capacity!$J$5 -> 4 | G21: =Capacity!$K$5 -> 1 | H21: =Capacity!$L$5 -> 760 | I21: =Capacity!$M$5 | J21: =Capacity!$N$5 | K21: =Capacity!$O$5 | L21: Monthly | M21: =Capacity!$Y$5 -> 68.085106 | N21: =Capacity!$Z$5 -> 64.680851 | O21: =Capacity!$AA$5 -> -3.4042553
A22: FY27 | B22: 2 | C22: 42-44 | D22: Coils | E22: =Capacity!$E$6 -> 0 | F22: =Capacity!$J$6 -> 0 | G22: =Capacity!$K$6 -> 0 | H22: =Capacity!$L$6 | I22: =Capacity!$M$6 | J22: =Capacity!$N$6 | K22: =Capacity!$O$6 | L22: Yearly | M22: =Capacity!$P$6 -> 0 | N22: =Capacity!$Q$6 -> 0 | O22: =Capacity!$R$6 -> 0
A23: FY27 | B23: 2 | C23: 42-44 | D23: Exciters | E23: =Capacity!$F$6 -> 0 | F23: =Capacity!$J$6 -> 0 | G23: =Capacity!$K$6 -> 0 | H23: =Capacity!$L$6 | I23: =Capacity!$M$6 | J23: =Capacity!$N$6 | K23: =Capacity!$O$6 | L23: Yearly | M23: =Capacity!$P$6 -> 0 | N23: =Capacity!$Q$6 -> 0 | O23: =Capacity!$R$6 -> 0
A24: FY27 | B24: 2 | C24: 42-44 | D24: RF | E24: =Capacity!$G$6 -> 0 | F24: =Capacity!$J$6 -> 0 | G24: =Capacity!$K$6 -> 0 | H24: =Capacity!$L$6 | I24: =Capacity!$M$6 | J24: =Capacity!$N$6 | K24: =Capacity!$O$6 | L24: Yearly | M24: =Capacity!$P$6 -> 0 | N24: =Capacity!$Q$6 -> 0 | O24: =Capacity!$R$6 -> 0
A25: FY27 | B25: 2 | C25: 42-44 | D25: WC | E25: =Capacity!$H$6 -> 0 | F25: =Capacity!$J$6 -> 0 | G25: =Capacity!$K$6 -> 0 | H25: =Capacity!$L$6 | I25: =Capacity!$M$6 | J25: =Capacity!$N$6 | K25: =Capacity!$O$6 | L25: Yearly | M25: =Capacity!$P$6 -> 0 | N25: =Capacity!$Q$6 -> 0 | O25: =Capacity!$R$6 -> 0
A26: FY27 | B26: 2 | C26: 42-44 | D26: FA | E26: =Capacity!$I$6 -> 0 | F26: =Capacity!$J$6 -> 0 | G26: =Capacity!$K$6 -> 0 | H26: =Capacity!$L$6 | I26: =Capacity!$M$6 | J26: =Capacity!$N$6 | K26: =Capacity!$O$6 | L26: Yearly | M26: =Capacity!$P$6 -> 0 | N26: =Capacity!$Q$6 -> 0 | O26: =Capacity!$R$6 -> 0
A27: FY26 | B27: 1 | C27: 1800's | D27: Coils | E27: =Capacity!$E$41 -> 8 | F27: =Capacity!$J$41 -> 8 | G27: =Capacity!$K$41 -> 4 | H27: =Capacity!$L$41 | I27: =Capacity!$M$41 | J27: =Capacity!$N$41 | K27: =Capacity!$O$41 -> 4160 | L27: Yearly | M27: =Capacity!$P$41 -> 5117 | N27: =Capacity!$Q$41 -> 4160 | O27: =Capacity!$R$41 -> -957
A28: FY26 | B28: 1 | C28: 1800's | D28: Exciters | E28: =Capacity!$F$41 -> 8 | F28: =Capacity!$J$41 -> 8 | G28: =Capacity!$K$41 -> 4 | H28: =Capacity!$L$41 | I28: =Capacity!$M$41 | J28: =Capacity!$N$41 | K28: =Capacity!$O$41 -> 4160 | L28: Yearly | M28: =Capacity!$P$41 -> 5117 | N28: =Capacity!$Q$41 -> 4160 | O28: =Capacity!$R$41 -> -957
A29: FY26 | B29: 1 | C29: 1800's | D29: RF | E29: =Capacity!$G$41 -> 8 | F29: =Capacity!$J$41 -> 8 | G29: =Capacity!$K$41 -> 4 | H29: =Capacity!$L$41 | I29: =Capacity!$M$41 | J29: =Capacity!$N$41 | K29: =Capacity!$O$41 -> 4160 | L29: Yearly | M29: =Capacity!$P$41 -> 5117 | N29: =Capacity!$Q$41 -> 4160 | O29: =Capacity!$R$41 -> -957
A30: FY26 | B30: 1 | C30: 1800's | D30: WC | E30: =Capacity!$H$41 -> 8 | F30: =Capacity!$J$41 -> 8 | G30: =Capacity!$K$41 -> 4 | H30: =Capacity!$L$41 | I30: =Capacity!$M$41 | J30: =Capacity!$N$41 | K30: =Capacity!$O$41 -> 4160 | L30: Yearly | M30: =Capacity!$P$41 -> 5117 | N30: =Capacity!$Q$41 -> 4160 | O30: =Capacity!$R$41 -> -957
A31: FY26 | B31: 1 | C31: 1800's | D31: FA | E31: =Capacity!$I$41 -> 8 | F31: =Capacity!$J$41 -> 8 | G31: =Capacity!$K$41 -> 4 | H31: =Capacity!$L$41 | I31: =Capacity!$M$41 | J31: =Capacity!$N$41 | K31: =Capacity!$O$41 -> 4160 | L31: Yearly | M31: =Capacity!$P$41 -> 5117 | N31: =Capacity!$Q$41 -> 4160 | O31: =Capacity!$R$41 -> -957
A32: FY26 | B32: 1 | C32: 1800's | D32: Coils | E32: =Capacity!$E$41 -> 8 | F32: =Capacity!$J$41 -> 8 | G32: =Capacity!$K$41 -> 4 | H32: =Capacity!$L$41 | I32: =Capacity!$M$41 | J32: =Capacity!$N$41 | K32: =Capacity!$O$41 -> 4160 | L32: Daily | M32: =Capacity!$S$41 -> 19.680769 | N32: =Capacity!$T$41 -> 16 | O32: =Capacity!$U$41 -> -3.6807692
A33: FY26 | B33: 1 | C33: 1800's | D33: Exciters | E33: =Capacity!$F$41 -> 8 | F33: =Capacity!$J$41 -> 8 | G33: =Capacity!$K$41 -> 4 | H33: =Capacity!$L$41 | I33: =Capacity!$M$41 | J33: =Capacity!$N$41 | K33: =Capacity!$O$41 -> 4160 | L33: Daily | M33: =Capacity!$S$41 -> 19.680769 | N33: =Capacity!$T$41 -> 16 | O33: =Capacity!$U$41 -> -3.6807692
A34: FY26 | B34: 1 | C34: 1800's | D34: RF | E34: =Capacity!$G$41 -> 8 | F34: =Capacity!$J$41 -> 8 | G34: =Capacity!$K$41 -> 4 | H34: =Capacity!$L$41 | I34: =Capacity!$M$41 | J34: =Capacity!$N$41 | K34: =Capacity!$O$41 -> 4160 | L34: Daily | M34: =Capacity!$S$41 -> 19.680769 | N34: =Capacity!$T$41 -> 16 | O34: =Capacity!$U$41 -> -3.6807692
A35: FY26 | B35: 1 | C35: 1800's | D35: WC | E35: =Capacity!$H$41 -> 8 | F35: =Capacity!$J$41 -> 8 | G35: =Capacity!$K$41 -> 4 | H35: =Capacity!$L$41 | I35: =Capacity!$M$41 | J35: =Capacity!$N$41 | K35: =Capacity!$O$41 -> 4160 | L35: Daily | M35: =Capacity!$S$41 -> 19.680769 | N35: =Capacity!$T$41 -> 16 | O35: =Capacity!$U$41 -> -3.6807692
A36: FY26 | B36: 1 | C36: 1800's | D36: FA | E36: =Capacity!$I$41 -> 8 | F36: =Capacity!$J$41 -> 8 | G36: =Capacity!$K$41 -> 4 | H36: =Capacity!$L$41 | I36: =Capacity!$M$41 | J36: =Capacity!$N$41 | K36: =Capacity!$O$41 -> 4160 | L36: Daily | M36: =Capacity!$S$41 -> 19.680769 | N36: =Capacity!$T$41 -> 16 | O36: =Capacity!$U$41 -> -3.6807692
A37: FY26 | B37: 1 | C37: 1800's | D37: Coils | E37: =Capacity!$I$41 -> 8 | F37: =Capacity!$J$41 -> 8 | G37: =Capacity!$K$41 -> 4 | H37: =Capacity!$L$41 | I37: =Capacity!$M$41 | J37: =Capacity!$N$41 | K37: =Capacity!$O$41 -> 4160 | L37: Shift | M37: =Capacity!$V$41 -> 9.8403846 | N37: =Capacity!$W$41 -> 8 | O37: =Capacity!$X$41 -> -1.8403846
A38: FY26 | B38: 1 | C38: 1800's | D38: Exciters | E38: =Capacity!$I$41 -> 8 | F38: =Capacity!$J$41 -> 8 | G38: =Capacity!$K$41 -> 4 | H38: =Capacity!$L$41 | I38: =Capacity!$M$41 | J38: =Capacity!$N$41 | K38: =Capacity!$O$41 -> 4160 | L38: Shift | M38: =Capacity!$V$41 -> 9.8403846 | N38: =Capacity!$W$41 -> 8 | O38: =Capacity!$X$41 -> -1.8403846
A39: FY26 | B39: 1 | C39: 1800's | D39: RF | E39: =Capacity!$I$41 -> 8 | F39: =Capacity!$J$41 -> 8 | G39: =Capacity!$K$41 -> 4 | H39: =Capacity!$L$41 | I39: =Capacity!$M$41 | J39: =Capacity!$N$41 | K39: =Capacity!$O$41 -> 4160 | L39: Shift | M39: =Capacity!$V$41 -> 9.8403846 | N39: =Capacity!$W$41 -> 8 | O39: =Capacity!$X$41 -> -1.8403846
A40: FY26 | B40: 1 | C40: 1800's | D40: WC | E40: =Capacity!$I$41 -> 8 | F40: =Capacity!$J$41 -> 8 | G40: =Capacity!$K$41 -> 4 | H40: =Capacity!$L$41 | I40: =Capacity!$M$41 | J40: =Capacity!$N$41 | K40: =Capacity!$O$41 -> 4160 | L40: Shift | M40: =Capacity!$V$41 -> 9.8403846 | N40: =Capacity!$W$41 -> 8 | O40: =Capacity!$X$41 -> -1.8403846
...

Sheet Demand
B1: POWER Business - INDUSTRIAL MASTER PLAN
D4: Customer DEMAND By Frame & LV/MHV
D6: Region | E6: LV/MHV | F6: cust. | G6: Frame | H6: FY25 | I6: FY26 | J6: FY27 | K6: FY28 | L6: FY29 | M6: FY30 | P6: Source
B8: EMEA | D8: EMEA | E8: LV | G8: 52 | H8: 995 | I8: 1122 | J8: 1132 | K8: 1217 | L8: 1295
L9: mixed on olo 2
D10: EMEA | E10: LV | G10: 53 | H10: 329 | I10: 442 | J10: 385 | K10: 395 | L10: 405
D11: EMEA | E11: LV | G11: 54 | H11: 470 | I11: 892 | J11: 1585 | K11: 2010 | L11: 2425
D13: EMEA | E13: MHV | G13: 52 | H13: 20 | I13: 13 | J13: 28 | K13: 28 | L13: 28
D14: EMEA | E14: MHV | G14: 53 | H14: 137 | I14: 207 | J14: 168 | K14: 202 | L14: 221
D15: EMEA | E15: MHV | G15: 54 | H15: 572 | I15: 705 | J15: 1071 | K15: 1344 | L15: 1569
D17: EMEA | E17: LV | G17: 55 | H17: 7 | I17: 83 | J17: 208 | K17: 242 | L17: 273
D18: EMEA | E18: MHV | G18: 55 | H18: 13 | I18: 131 | J18: 234 | K18: 300 | L18: 365
D21: EMEA | E21: MHV | G21: 56 | H21: 71 | I21: 88 | J21: 81 | K21: 62 | L21: 65
D22: EMEA | E22: MHV | G22: 58 | H22: 44 | I22: 71 | J22: 92 | K22: 84 | L22: 94
D23: EMEA | E23: MHV | G23: 60 | H23: 19 | I23: 48 | J23: 91 | K23: 133 | L23: 142
D26: EMEA | E26: MHV | G26: 61 4P | H26: 0 | I26: 0 | J26: 0 | K26: 0 | L26: 0
D27: EMEA | E27: MHV | G27: 62 | H27: 2 | I27: 10 | J27: 17 | K27: 20 | L27: 25
B32: ASIA | D32: Asia | E32: LV | G32: 52 | H32: 2711 | I32: 3710 | J32: 4056 | K32: 4413 | L32: 5420
D33: Asia | E33: LV | G33: 53 | H33: 258 | I33: 540 | J33: 615 | K33: 750 | L33: 895
D34: Asia | E34: LV | G34: 54 | H34: 467 | I34: 1184 | J34: 1376 | K34: 1552 | L34: 710
D35: Asia | E35: LV | F35: CAT | G35: 1400 | H35: 43 | I35: 44 | J35: 50 | K35: 60 | L35: 80
D36: Asia | E36: LV | F36: CAT | G36: 1600 | H36: 119 | I36: 206 | J36: 216 | K36: 223 | L36: 236
D37: Asia | E37: LV | F37: CAT CN | G37: 1800 | H37: 105 | I37: 297 | J37: 294 | K37: 292 | L37: 300
D38: Asia | E38: MHV | F38: US | G38: 2700/3000 | H38: 116 | I38: 776 | J38: 1383 | K38: 1476 | L38: 1490
D39: Asia | E39: LV | F39: CAT US | G39: 1800 | H39: 525 | I39: 120 | J39: 240 | K39: 280 | L39: 300
D41: Asia | E41: MHV | G41: 52 | H41: 217 | I41: 497 | J41: 609 | K41: 752 | L41: 1023
D42: Asia | E42: MHV | G42: 53 | H42: 4112 | I42: 4890 | J42: 6365 | K42: 7720 | L42: 8262
D43: Asia | E43: MHV | G43: 54 | H43: 389 | I43: 650 | J43: 1055 | K43: 1260 | L43: 1135
D44: Asia | E44: MHV | G44: 55 | H44: 61 | I44: 115 | J44: 121 | K44: 127 | L44: 135
D45: Asia | E45: LV | G45: 55 | H45: 2 | I45: 1 | J45: 1 | K45: 1 | L45: 0
D47: Asia | E47: MHV | G47: 56 equ | H47: 130 | I47: 200 | J47: 180 | K47: 150 | L47: 149
D48: Asia | E48: MHV | G48: 58 equ | H48: 70 | I48: 70 | J48: 70 | K48: 70 | L48: 44
B53: INDIA | D53: India | E53: LV | G53: 52.3 | H53: 250 | I53: 325 | J53: 420 | K53: 525 | L53: 600
D54: India | E54: LV | G54: 53.2 | H54: 120 | I54: 400 | J54: 500 | K54: 600 | L54: 650
D55: India | E55: LV | G55: 54.2 | H55: 5 | I55: 250 | J55: 475 | K55: 775 | L55: 800
D56: India | E56: LV | G56: WTG G54/55 | H56: - | I56: 25 | J56: 50 | K56: 100 | L56: 100
D58: India | E58: LV | F58: US | G58: 1800 RW | H58: 250 | I58: 1200 | J58: 1800 | K58: 1800 | L58: 1800
D60: India | E60: MHV | G60: 52.3 | H60: 5 | I60: 5 | J60: 5 | K60: 10 | L60: 10
D61: India | E61: MHV | G61: 53.2 | H61: 260 | I61: 370 | J61: 250 | K61: 290 | L61: 365
D62: India | E62: MHV | G62: 54.2/55 | H62: 115 | I62: 125 | J62: 150 | K62: 200 | L62: 225
...

Sheet Sheet2
C2: Fiscal Year | D2: Value Strem | E2: Demand
C3: FY26 | D3: 42 - 44
C4: FY27 | D4: 42 - 44
C5: FY28 | D5: 42 - 44
C6: FY29 | D6: 42 - 44
C7: FY26 | D7: 46's
C8: FY27 | D8: 46's
C9: FY28 | D9: 46's
C10: FY29 | D10: 46's
C11: FY26 | D11: 47's
C12: FY27 | D12: 47's
C13: FY28 | D13: 47's
C14: FY29 | D14: 47's
... C42: FY29 | D42: 1800's
